<?xml version="1.0" ?>
<robot name="traffic_lights" xmlns:xacro="http://ros.org/wiki/xacro">

    <link name="world"/>

    <joint name="base_joint_1" type="fixed">
        <parent link="world"/>
        <child link="base_link_1"/>
        <origin xyz="0 0 0.1" rpy="1.57 0 0"/>
    </joint>

    <link name="base_link_1">
        <visual>
            <geometry>
                <box size="0.1 0.03 0.005"/>
            </geometry>
        </visual>

        <collision>
            <origin xyz="0 0 0.001" rpy="0 0 0"/>
            <geometry>
                <box size="0.09 0.029 0.0049"/>
            </geometry>
        </collision>

        <inertial>
            <origin xyz="0 0 0" rpy="0 0 0"/>
            <mass value="0.1"/>
            <inertia ixx="0.0001" ixy="0" ixz="0"
                     iyy="0.0001" iyz="0"
                     izz="0.0001" />
        </inertial>
    </link>
    <gazebo reference="base_link_1">
        <material> Gazebo/Gray </material>
    </gazebo>

    <link name="light_red">
        <visual>
            <geometry>
                <cylinder length="0.003" radius="0.009"/>
            </geometry>
        </visual>
        <inertial>
            <origin xyz="0 0 0" rpy="0 0 0"/>
            <mass value="0.01"/>
            <inertia ixx="0.0001" ixy="0" ixz="0"
                    iyy="0.0001" iyz="0"
                    izz="0.0001" />
        </inertial>
        <gravity>0</gravity>
    </link>
    <joint name="base_to_light_red_1" type="prismatic">
        <parent link="base_link_1"/>
        <child link="light_red"/>
        <origin xyz="-0.0333 0.0 0.0" rpy="0 0 0"/>
        <axis xyz="0 0 1"/>
        <limit lower="0.0" upper="0.002" effort="1000.0" velocity="1000.0"/>
        <dynamics damping="0.0" friction="0.1"/>
    </joint>

    <link name="light_orange">
        <visual>
            <geometry>
                <cylinder length="0.003" radius="0.009"/>
            </geometry>
        </visual>
        <inertial>
            <origin xyz="0 0 0" rpy="0 0 0"/>
            <mass value="0.01"/>
            <inertia ixx="0.0001" ixy="0" ixz="0"
                    iyy="0.0001" iyz="0"
                    izz="0.0001" />
        </inertial>
        <gravity>0</gravity>
    </link>
    <joint name="base_to_light_orange_1" type="prismatic">
        <parent link="base_link_1"/>
        <child link="light_orange"/>
        <origin xyz="0.0 0.0 0.0" rpy="0 0 0"/>
        <axis xyz="0 0 1"/>
        <limit lower="0.0" upper="0.002" effort="1000.0" velocity="1000.0"/>
        <dynamics damping="0.0" friction="0.1"/>
    </joint>

    <link name="light_green">
        <visual>
            <geometry>
                <cylinder length="0.003" radius="0.009"/>
            </geometry>
        </visual>
        <inertial>
            <origin xyz="0 0 0" rpy="0 0 0"/>
            <mass value="0.01"/>
            <inertia ixx="0.0001" ixy="0" ixz="0"
                    iyy="0.0001" iyz="0"
                    izz="0.0001" />
        </inertial>
        <gravity>0</gravity>
    </link>
    <joint name="base_to_light_green_1" type="prismatic">
        <parent link="base_link_1"/>
        <child link="light_green"/>
        <origin xyz="0.0333 0.0 0.0" rpy="0 0 0"/>
        <axis xyz="0 0 1"/>
        <limit lower="0.0" upper="0.002" effort="1000.0" velocity="1000.0"/>
        <dynamics damping="0.0" friction="0.1"/>
    </joint>

    <gazebo reference="light_red">
        <material> Gazebo/Red </material>
    </gazebo>
    <gazebo reference="light_orange">
        <material> Gazebo/Orange </material>
    </gazebo>
    <gazebo reference="light_green">
        <material> Gazebo/Green </material>
    </gazebo>

    <gazebo>
        <plugin name="gazebo_ros_control" filename="libgazebo_ros_control.so">
            <robotNamespace>/traffic_lights_1</robotNamespace>
        </plugin>
    </gazebo>

    <transmission name="light_1_trans">
        <type>transmission_interface/SimpleTransmission</type>
        <actuator name="motor1">
            <mechanicalReduction>1</mechanicalReduction>
        </actuator>
        <joint name="base_to_light_green_1">
            <hardwareInterface>hardware_interface/EffortJointInterface</hardwareInterface>
        </joint>
    </transmission>

    <transmission name="base_to_light_orange_trans">
        <type>transmission_interface/SimpleTransmission</type>
        <actuator name="light2">
            <mechanicalReduction>1</mechanicalReduction>
        </actuator>
        <joint name="base_to_light_orange">
            <hardwareInterface>hardware_interface/EffortJointInterface</hardwareInterface>
        </joint>
    </transmission>

    <transmission name="base_to_light_red_trans">
        <type>transmission_interface/SimpleTransmission</type>
        <actuator name="light3">
            <mechanicalReduction>1</mechanicalReduction>
        </actuator>
        <joint name="base_to_light_red">
            <hardwareInterface>hardware_interface/EffortJointInterface</hardwareInterface>
        </joint>
    </transmission>




</robot>