<?xml version="1.0" ?>
<!--This file contains the URDF/Gazebo description of a Barrier. Used in the package stage_arene_ros.
    Structure:
        link :   world (fixed in the simulation)
        joint:  world <-> base_link (fixed)
        link :   base_link (base box of the barrier)
        joint:  base_link <-> barrier (revolute [-1.57:0] )
        link :   barrier (moving part of the barrier)
    Parameters:
        LINK : visual, collision, inertial
        JOINT: type, parent, child, origin, [limit], [dynamics]-->

<robot name="barrier">

    <link name="world"/>

    <!-- This joint fixes base_link to the world, position defined by origin -->
    <joint name="barrier_joint" type="fixed">
        <parent link="world"/>
        <child link="base_link"/>
        <origin xyz="-1.50 0.9 0.025" rpy="0 0 1.57"/>
    </joint>

    <link name="base_link">

        <visual>
            <geometry>
                <box size="0.05 0.05 0.05"/>
            </geometry>
        </visual>

        <collision>
            <origin xyz="0 0 0" rpy="0 0 0"/>
            <geometry>
                <box size="0.05 0.05 0.005"/>
            </geometry>
        </collision>

        <inertial>
            <origin xyz="0 0 0" rpy="0 0 0"/>
            <mass value="0.1"/>
            <inertia    ixx="0.0001" ixy="0" ixz="0"
                        iyy="0.0001" iyz="0"
                        izz="0.0001" />
        </inertial>

    </link>

    <!-- This joint allows revolute moving part, axis position on the base defined in origin here -->
    <joint name="base_to_barrier" type="revolute"> 
        <parent link="base_link"/>
        <child link="barrier"/>
        <origin xyz="-0.025 0.025 0.0" rpy="1.57 0 0"/>
        <axis xyz="0 0 1"/>
        <limit effort="1000" lower="-1.57" upper="0" velocity="1.0"/>
        <dynamics damping="0.0" friction="0.1"/>
    </joint>


    <link name="barrier">
        <!-- The axis position on the moving part is defined in origin here -->
        <visual>
            <origin xyz="-0.125 0.04 -0.0025" rpy="0 0 0"/>
            <geometry>
                <box size="0.3 0.08 0.005"/>
            </geometry>
        </visual>

        <collision>
            <origin xyz="-0.125 0.04 -0.0025" rpy="0 0 0"/>
            <geometry>
                <box size="0.3 0.08 0.005"/>
            </geometry>
        </collision>

        <inertial>
            <origin xyz="0 0 0" rpy="0 0 0"/>
            <mass value="0.1"/>
            <inertia    ixx="0.0001" ixy="0" ixz="0"
                        iyy="0.0001" iyz="0"
                        izz="0.0001" />
        </inertial>

    </link>

    <!-- Gazebo colors -->
    <gazebo reference="base_link">
        <material>Gazebo/Gray</material> 
    </gazebo>

    <gazebo reference="barrier">
        <material>Gazebo/Red</material>
    </gazebo>
    
</robot>
