<?xml version="1.0" ?>
<robot name="barrier" xmlns:xacro="http://ros.org/wiki/xacro">
  
  <link name="world"/>

<!-- barrier 1 -->
  <joint name="base_joint_1" type="fixed">
    <parent link="world"/>
    <child link="base_link_1"/>
    <origin xyz="-1.5 0.9 0.01" rpy="0 0 1.57"/>
  </joint>

  <link name="base_link_1">
    <visual>
      <geometry>
        <box size="0.05 0.05 0.005"/>
      </geometry>
    </visual>

    <collision>
      <origin xyz="0 0 0" rpy="0 0 0"/>
      <geometry>
        <box size="0.05 0.05 0.005"/>
      </geometry>
    </collision>

    <inertial>
      <origin xyz="0 0 0" rpy="0 0 0"/>
      <mass value="0.1"/>
      <inertia  ixx="0.0001" ixy="0" ixz="0"
                iyy="0.0001" iyz="0"
                izz="0.0001" />
    </inertial>
  </link>

  <link name="motor_1">
    <inertial>
      <mass value="0.1"/>
      <origin xyz="0 0 0" rpy="0 0 0"/>
      <inertia  ixx="0.01" ixy="0" ixz="0"
                iyy="0.01" iyz="0"
                izz="0.01" />
    </inertial>
    <collision>
      <origin xyz="0 0 0" rpy="0 0 0"/>
      <geometry>
        <box size="0.04 0.037 0.02"/>
      </geometry>
    </collision>
    <visual>
      <geometry>
        <box size="0.04 0.037 0.02"/>
      </geometry>
    </visual>
  </link>

  <joint name="base_to_motor_1" type="fixed">
    <parent link="base_link_1"/>
    <child link="motor_1"/>
    <origin xyz="0 0 0.0125" rpy="0 0 0"/>
  </joint>

  <link name="gear_1">
    <inertial>
      <mass value="0.1"/>
      <origin xyz="0 0 0" rpy="0 0 0"/>
      <inertia ixx="0.01" ixy="0" ixz="0"
              iyy="0.01" iyz="0"
              izz="0.01" />
    </inertial>
    <collision>
      <origin xyz="0.01 0.021 0" rpy="-1.57 3.14 0"/>
      <geometry>
        <cylinder radius="0.01" length="0.005"/>
      </geometry>
    </collision>
    <visual>
        <geometry>
            <cylinder radius="0.01" length="0.005"/>
        </geometry>
    </visual>
  </link>

  <joint name="motor_to_gear_1" type="fixed">
      <parent link="motor_1"/>
      <child link="gear_1"/>
      <origin xyz="0.01 0.021 0" rpy="-1.57 3.14 0"/>
  </joint>

  <link name="barrier_1">
    <inertial>
      <mass value="0.01"/>
      <origin xyz="0 0 0" rpy="0 0 0"/>
      <inertia ixx="0.01" ixy="0" ixz="0"
              iyy="0.01" iyz="0"
              izz="0.01" />
    </inertial>
    <collision>
      <origin xyz="0.14 0.02 0.0005" rpy="0 0 0"/>
      <geometry>
        <box size="0.3 0.06 0.001"/>
      </geometry>
    </collision>
    <visual>
      <origin xyz="0.14 0.02 0.0005" rpy="0 0 0"/>
      <geometry>
        <box size="0.3 0.06 0.001"/>
      </geometry>
    </visual>
  </link>

  <joint name="gear_to_barrier_1" type="revolute">
      <limit upper="1.57" lower="0" velocity="100" effort="100"/>
      <origin xyz="0 0 0.0025 " rpy="0 0 0"/>
      <axis xyz="0 0 1"/>
      <parent link="gear_1"/>
      <child link="barrier_1"/>
      <dynamics damping="0.1" friction="0.1"/>
  </joint>

  <gazebo>
    <plugin name="gazebo_ros_control" filename="libgazebo_ros_control.so">
      <robotNamespace>/barrier_1</robotNamespace>
    </plugin>
  </gazebo>

  <transmission name="gear_to_barrier_1_trans">
    <type>transmission_interface/SimpleTransmission</type>
    <actuator name="motor1">
      <mechanicalReduction>1</mechanicalReduction>
    </actuator>
    <joint name="gear_to_barrier_1">
      <hardwareInterface>hardware_interface/EffortJointInterface</hardwareInterface>
    </joint>
  </transmission>


  <gazebo reference="base_link_1">
    <material>Gazebo/DarkGrey</material>
  </gazebo>

  <gazebo reference="motor_1">
    <material>Gazebo/Black</material>
  </gazebo>

  <gazebo reference="gear_1">
    <material>Gazebo/Grey</material>
  </gazebo>

  <gazebo reference="barrier_1">
    <material>Gazebo/Yellow</material>
  </gazebo>
<!-- barrier 2 -->
  <joint name="base_joint_2" type="fixed">
    <parent link="world"/>
    <child link="base_link_2"/>
    <origin xyz="-1.1 -1.6 0.01" rpy="0 0 3.14"/>
  </joint>

  <link name="base_link_2">
    <visual>
      <geometry>
        <box size="0.05 0.05 0.005"/>
      </geometry>
    </visual>

    <collision>
      <origin xyz="0 0 0" rpy="0 0 0"/>
      <geometry>
        <box size="0.05 0.05 0.005"/>
      </geometry>
    </collision>

    <inertial>
      <origin xyz="0 0 0" rpy="0 0 0"/>
      <mass value="0.1"/>
      <inertia  ixx="0.0001" ixy="0" ixz="0"
                iyy="0.0001" iyz="0"
                izz="0.0001" />
    </inertial>
  </link>

  <link name="motor_2">
    <inertial>
      <mass value="0.1"/>
      <origin xyz="0 0 0" rpy="0 0 0"/>
      <inertia  ixx="0.01" ixy="0" ixz="0"
                iyy="0.01" iyz="0"
                izz="0.01" />
    </inertial>
    <collision>
      <origin xyz="0 0 0" rpy="0 0 0"/>
      <geometry>
        <box size="0.04 0.037 0.02"/>
      </geometry>
    </collision>
    <visual>
      <geometry>
        <box size="0.04 0.037 0.02"/>
      </geometry>
    </visual>
  </link>

  <joint name="base_to_motor_2" type="fixed">
    <parent link="base_link_2"/>
    <child link="motor_2"/>
    <origin xyz="0 0 0.0125" rpy="0 0 0"/>
  </joint>

  <link name="gear_2">
    <inertial>
      <mass value="0.1"/>
      <origin xyz="0 0 0" rpy="0 0 0"/>
      <inertia ixx="0.01" ixy="0" ixz="0"
              iyy="0.01" iyz="0"
              izz="0.01" />
    </inertial>
    <collision>
      <origin xyz="0.01 0.021 0" rpy="-1.57 3.14 0"/>
      <geometry>
        <cylinder radius="0.01" length="0.005"/>
      </geometry>
    </collision>
    <visual>
        <geometry>
            <cylinder radius="0.01" length="0.005"/>
        </geometry>
    </visual>
  </link>

  <joint name="motor_to_gear_2" type="fixed">
      <parent link="motor_2"/>
      <child link="gear_2"/>
      <origin xyz="0.01 0.021 0" rpy="-1.57 3.14 0"/>
  </joint>

  <link name="barrier_2">
    <inertial>
      <mass value="0.01"/>
      <origin xyz="0 0 0" rpy="0 0 0"/>
      <inertia ixx="0.01" ixy="0" ixz="0"
              iyy="0.01" iyz="0"
              izz="0.01" />
    </inertial>
    <collision>
      <origin xyz="0.14 0.02 0.0005" rpy="0 0 0"/>
      <geometry>
        <box size="0.3 0.06 0.001"/>
      </geometry>
    </collision>
    <visual>
      <origin xyz="0.14 0.02 0.0005" rpy="0 0 0"/>
      <geometry>
        <box size="0.3 0.06 0.001"/>
      </geometry>
    </visual>
  </link>

  <joint name="gear_to_barrier_2" type="revolute">
      <limit upper="1.57" lower="0" velocity="100" effort="100"/>
      <origin xyz="0 0 0.0025 " rpy="0 0 0"/>
      <axis xyz="0 0 1"/>
      <parent link="gear_2"/>
      <child link="barrier_2"/>
      <dynamics damping="0.1" friction="0.1"/>
  </joint>

  <gazebo>
    <plugin name="gazebo_ros_control" filename="libgazebo_ros_control.so">
      <robotNamespace>/barrier_2</robotNamespace>
    </plugin>
  </gazebo>

  <transmission name="gear_to_barrier_2_trans">
    <type>transmission_interface/SimpleTransmission</type>
    <actuator name="motor1">
      <mechanicalReduction>1</mechanicalReduction>
    </actuator>
    <joint name="gear_to_barrier_2">
      <hardwareInterface>hardware_interface/EffortJointInterface</hardwareInterface>
    </joint>
  </transmission>

  <gazebo reference="base_link_2">
    <material>Gazebo/DarkGrey</material>
  </gazebo>

  <gazebo reference="motor_2">
    <material>Gazebo/Black</material>
  </gazebo>

  <gazebo reference="gear_2">
    <material>Gazebo/Grey</material>
  </gazebo>

  <gazebo reference="barrier_2">
    <material>Gazebo/Yellow</material>
  </gazebo>

<!-- traffic light 1 -->
  <joint name="base_joint_1_tl" type="fixed">
      <parent link="world"/>
      <child link="base_link_1_tl"/>
      <origin xyz="-1.6 0.8 0.0001" rpy="0 0 1.57"/>
  </joint>

  <link name="base_link_1_tl">
      <visual>
          <geometry>
              <box size="0.1 0.03 0.005"/>
          </geometry>
      </visual>

      <collision>
          <origin xyz="0 0 0.001" rpy="0 0 0"/>
          <geometry>
              <box size="0.09 0.029 0.0049"/>
          </geometry>
      </collision>

      <inertial>
          <origin xyz="0 0 0" rpy="0 0 0"/>
          <mass value="0.1"/>
          <inertia ixx="0.0001" ixy="0" ixz="0"
                    iyy="0.0001" iyz="0"
                    izz="0.0001" />
      </inertial>
  </link>
  <gazebo reference="base_link_1_tl">
      <material> Gazebo/Gray </material>
  </gazebo>

  <link name="light_red_1">
      <visual>
          <geometry>
              <cylinder length="0.003" radius="0.009"/>
          </geometry>
      </visual>
      <inertial>
          <origin xyz="0 0 0" rpy="0 0 0"/>
          <mass value="0.01"/>
          <inertia ixx="0.0001" ixy="0" ixz="0"
                  iyy="0.0001" iyz="0"
                  izz="0.0001" />
      </inertial>
      <gravity>0</gravity>
  </link>
  <joint name="base_to_light_red_1" type="prismatic">
      <parent link="base_link_1_tl"/>
      <child link="light_red_1"/>
      <origin xyz="-0.0333 0.0 0.0" rpy="0 0 0"/>
      <axis xyz="0 0 1"/>
      <limit lower="0.0" upper="0.002" effort="1000.0" velocity="1000.0"/>
      <dynamics damping="0.0" friction="0.1"/>
  </joint>

  <link name="light_yellow_1">
      <visual>
          <geometry>
              <cylinder length="0.003" radius="0.009"/>
          </geometry>
      </visual>
      <inertial>
          <origin xyz="0 0 0" rpy="0 0 0"/>
          <mass value="0.01"/>
          <inertia ixx="0.0001" ixy="0" ixz="0"
                  iyy="0.0001" iyz="0"
                  izz="0.0001" />
      </inertial>
      <gravity>0</gravity>
  </link>
  <joint name="base_to_light_yellow_1" type="prismatic">
      <parent link="base_link_1_tl"/>
      <child link="light_yellow_1"/>
      <origin xyz="0.0 0.0 0.0" rpy="0 0 0"/>
      <axis xyz="0 0 1"/>
      <limit lower="0.0" upper="0.002" effort="1000.0" velocity="1000.0"/>
      <dynamics damping="0.0" friction="0.1"/>
  </joint>

  <link name="light_green_1">
      <visual>
          <geometry>
              <cylinder length="0.003" radius="0.009"/>
          </geometry>
      </visual>
      <inertial>
          <origin xyz="0 0 0" rpy="0 0 0"/>
          <mass value="0.01"/>
          <inertia ixx="0.0001" ixy="0" ixz="0"
                  iyy="0.0001" iyz="0"
                  izz="0.0001" />
      </inertial>
      <gravity>0</gravity>
  </link>
  <joint name="base_to_light_green_1" type="prismatic">
      <parent link="base_link_1_tl"/>
      <child link="light_green_1"/>
      <origin xyz="0.0333 0.0 0.0" rpy="0 0 0"/>
      <axis xyz="0 0 1"/>
      <limit lower="0.0" upper="0.002" effort="1000.0" velocity="1000.0"/>
      <dynamics damping="0.0" friction="0.1"/>
  </joint>

  <gazebo reference="light_red_1">
      <material> Gazebo/Red </material>
  </gazebo>
  <gazebo reference="light_yellow_1">
      <material> Gazebo/Yellow </material>
  </gazebo>
  <gazebo reference="light_green_1">
      <material> Gazebo/Green </material>
  </gazebo>

  <gazebo>
      <plugin name="gazebo_ros_control" filename="libgazebo_ros_control.so">
          <robotNamespace>/traffic_lights_1</robotNamespace>
      </plugin>
  </gazebo>

  <transmission name="base_to_light_1_green_trans">
      <type>transmission_interface/SimpleTransmission</type>
      <actuator name="motor1">
          <mechanicalReduction>1</mechanicalReduction>
      </actuator>
      <joint name="base_to_light_green_1">
          <hardwareInterface>hardware_interface/EffortJointInterface</hardwareInterface>
      </joint>
  </transmission>

  <transmission name="base_to_light_1_yellow_trans">
      <type>transmission_interface/SimpleTransmission</type>
      <actuator name="motor1">
          <mechanicalReduction>1</mechanicalReduction>
      </actuator>
      <joint name="base_to_light_yellow_1">
          <hardwareInterface>hardware_interface/EffortJointInterface</hardwareInterface>
      </joint>
  </transmission>

  <transmission name="base_to_light_1_red_trans">
      <type>transmission_interface/SimpleTransmission</type>
      <actuator name="motor1">
          <mechanicalReduction>1</mechanicalReduction>
      </actuator>
      <joint name="base_to_light_red_1">
          <hardwareInterface>hardware_interface/EffortJointInterface</hardwareInterface>
      </joint>
  </transmission>

<!-- traffic light 2 -->
  <joint name="base_joint_2_tl" type="fixed">
      <parent link="world"/>
      <child link="base_link_2_tl"/>
      <origin xyz="-1 -1.7 0.0001" rpy="0 0 0"/>
  </joint>

  <link name="base_link_2_tl">
      <visual>
          <geometry>
              <box size="0.1 0.03 0.005"/>
          </geometry>
      </visual>

      <collision>
          <origin xyz="0 0 0.001" rpy="0 0 0"/>
          <geometry>
              <box size="0.09 0.029 0.0049"/>
          </geometry>
      </collision>

      <inertial>
          <origin xyz="0 0 0" rpy="0 0 0"/>
          <mass value="0.1"/>
          <inertia ixx="0.0001" ixy="0" ixz="0"
                    iyy="0.0001" iyz="0"
                    izz="0.0001" />
      </inertial>
  </link>
  <gazebo reference="base_link_2_tl">
      <material> Gazebo/Gray </material>
  </gazebo>

  <link name="light_red_2">
      <visual>
          <geometry>
              <cylinder length="0.003" radius="0.009"/>
          </geometry>
      </visual>
      <inertial>
          <origin xyz="0 0 0" rpy="0 0 0"/>
          <mass value="0.01"/>
          <inertia ixx="0.0001" ixy="0" ixz="0"
                  iyy="0.0001" iyz="0"
                  izz="0.0001" />
      </inertial>
      <gravity>0</gravity>
  </link>
  <joint name="base_to_light_red_2" type="prismatic">
      <parent link="base_link_2_tl"/>
      <child link="light_red_2"/>
      <origin xyz="-0.0333 0.0 0.0" rpy="0 0 0"/>
      <axis xyz="0 0 1"/>
      <limit lower="0.0" upper="0.002" effort="1000.0" velocity="1000.0"/>
      <dynamics damping="0.0" friction="0.1"/>
  </joint>

  <link name="light_yellow_2">
      <visual>
          <geometry>
              <cylinder length="0.003" radius="0.009"/>
          </geometry>
      </visual>
      <inertial>
          <origin xyz="0 0 0" rpy="0 0 0"/>
          <mass value="0.01"/>
          <inertia ixx="0.0001" ixy="0" ixz="0"
                  iyy="0.0001" iyz="0"
                  izz="0.0001" />
      </inertial>
      <gravity>0</gravity>
  </link>
  <joint name="base_to_light_yellow_2" type="prismatic">
      <parent link="base_link_2_tl"/>
      <child link="light_yellow_2"/>
      <origin xyz="0.0 0.0 0.0" rpy="0 0 0"/>
      <axis xyz="0 0 1"/>
      <limit lower="0.0" upper="0.002" effort="1000.0" velocity="1000.0"/>
      <dynamics damping="0.0" friction="0.1"/>
  </joint>

  <link name="light_green_2">
      <visual>
          <geometry>
              <cylinder length="0.003" radius="0.009"/>
          </geometry>
      </visual>
      <inertial>
          <origin xyz="0 0 0" rpy="0 0 0"/>
          <mass value="0.01"/>
          <inertia ixx="0.0001" ixy="0" ixz="0"
                  iyy="0.0001" iyz="0"
                  izz="0.0001" />
      </inertial>
      <gravity>0</gravity>
  </link>
  <joint name="base_to_light_green_2" type="prismatic">
      <parent link="base_link_2_tl"/>
      <child link="light_green_2"/>
      <origin xyz="0.0333 0.0 0.0" rpy="0 0 0"/>
      <axis xyz="0 0 1"/>
      <limit lower="0.0" upper="0.002" effort="1000.0" velocity="1000.0"/>
      <dynamics damping="0.0" friction="0.1"/>
  </joint>

  <gazebo reference="light_red_2">
      <material> Gazebo/Red </material>
  </gazebo>
  <gazebo reference="light_yellow_2">
      <material> Gazebo/Yellow </material>
  </gazebo>
  <gazebo reference="light_green_2">
      <material> Gazebo/Green </material>
  </gazebo>

  <gazebo>
      <plugin name="gazebo_ros_control" filename="libgazebo_ros_control.so">
          <robotNamespace>/traffic_lights_2</robotNamespace>
      </plugin>
  </gazebo>

  <transmission name="light_2_trans">
      <type>transmission_interface/SimpleTransmission</type>
      <actuator name="motor1">
          <mechanicalReduction>1</mechanicalReduction>
      </actuator>
      <joint name="base_to_light_green_2">
          <hardwareInterface>hardware_interface/EffortJointInterface</hardwareInterface>
      </joint>
  </transmission>

  <transmission name="base_to_light_2_yellow_trans">
      <type>transmission_interface/SimpleTransmission</type>
      <actuator name="motor1">
          <mechanicalReduction>1</mechanicalReduction>
      </actuator>
      <joint name="base_to_light_yellow_2">
          <hardwareInterface>hardware_interface/EffortJointInterface</hardwareInterface>
      </joint>
  </transmission>

  <transmission name="base_to_light_2_red_trans">
      <type>transmission_interface/SimpleTransmission</type>
      <actuator name="motor1">
          <mechanicalReduction>1</mechanicalReduction>
      </actuator>
      <joint name="base_to_light_red_2">
          <hardwareInterface>hardware_interface/EffortJointInterface</hardwareInterface>
      </joint>
  </transmission>

</robot>
