<?xml version="1.0" ?>
<robot name="traffic_light">

    <link name="world"/>

    <joint name="base_joint" type="fixed">
        <parent link="world"/>
        <child link="base_link"/>
        <origin xyz="-1.55 0.75 0.0025" rpy="0 0 1.57"/>
    </joint>

    <link name="base_link">

        <visual>
            <geometry>
                <box size="0.1 0.03 0.005"/>
            </geometry>
        </visual>

        <collision>
            <origin xyz="0 0 0" rpy="0 0 0"/>
            <geometry>
                <box size="0.1 0.03 0.005"/>
            </geometry>
        </collision>

        <inertial>
            <origin xyz="0 0 0" rpy="0 0 0"/>
            <mass value="0.1"/>
            <inertia ixx="0.0001" ixy="0" ixz="0"
                     iyy="0.0001" iyz="0"
                     izz="0.0001" />
        </inertial>

    </link>

    <link name="light_red">
        <visual>
            <geometry>
                <cylinder length="0.003" radius="0.009"/>
            </geometry>
        </visual>
        <inertial>
            <origin xyz="0 0 0" rpy="0 0 0"/>
            <mass value="0.01"/>
            <inertia ixx="0.0001" ixy="0" ixz="0"
                    iyy="0.0001" iyz="0"
                    izz="0.0001" />
        </inertial>
        <gravity>0</gravity>
    </link>

    <joint name="base_to_light_red" type="prismatic">
        <parent link="base_link"/>
        <child link="light_red"/>
        <origin xyz="-0.0333 0.0 0.0" rpy="0 0 0"/>
        <axis xyz="0 0 1"/>
        <limit lower="0.0" upper="0.002" effort="1000.0" velocity="1000.0"/>
        <dynamics damping="0.0" friction="0.1"/>
    </joint>

    <link name="light_yellow">
        <visual>
            <geometry>
                <cylinder length="0.003" radius="0.009"/>
            </geometry>
        </visual>
        <inertial>
            <origin xyz="0 0 0" rpy="0 0 0"/>
            <mass value="0.01"/>
            <inertia ixx="0.0001" ixy="0" ixz="0"
                    iyy="0.0001" iyz="0"
                    izz="0.0001" />
        </inertial>
        <gravity>0</gravity>
    </link>

    <joint name="base_to_light_yellow" type="prismatic">
        <parent link="base_link"/>
        <child link="light_yellow"/>
        <origin xyz="0 0 0" rpy="0 0 0"/>
        <axis xyz="0 0 1"/>
        <limit lower="0.0" upper="0.002" effort="1000.0" velocity="1000.0"/>
        <dynamics damping="0.0" friction="0.1"/>
    </joint>

    <link name="light_green">
        <visual>
            <geometry>
                <cylinder length="0.003" radius="0.009"/>
            </geometry>
        </visual>
        <inertial>
            <origin xyz="0 0 0" rpy="0 0 0"/>
            <mass value="0.01"/>
            <inertia ixx="0.0001" ixy="0" ixz="0"
                    iyy="0.0001" iyz="0"
                    izz="0.0001" />
        </inertial>
        <gravity>0</gravity>
    </link>

    <joint name="base_to_light_green" type="prismatic">
        <parent link="base_link"/>
        <child link="light_green"/>
        <origin xyz="0.0333 0 0" rpy="0 0 0"/>
        <axis xyz="0 0 1"/>
        <limit lower="0.0" upper="0.002" effort="1000.0" velocity="1000.0"/>
        <dynamics damping="0.0" friction="0.1"/>
    </joint>

    <gazebo reference="base_link">
        <material>Gazebo/Gray</material>
    </gazebo>

    <gazebo reference="light_red">
        <material>Gazebo/Red</material>
    </gazebo>

    <gazebo reference="light_yellow">
        <material>Gazebo/Yellow</material>
    </gazebo>

    <gazebo reference="light_green">
        <material>Gazebo/Green</material>
    </gazebo>

</robot>